Workbook

Sheet Cronograma
A1: QT PIZZA BAR · ENSAIO DE PRÉ-FERMENTOS
A2: Cronograma automático · braço B (biga a 55%) e braço C (biga a 65%)
A4: COMO USAR
A5: Edite só as células amarelas. Mude a hora da mistura da biga e todo o cronograma daquele braço se recalcula.
A6: Células cinza são para anotar à mão durante a produção: hora real e pH medido.
A7: Durações no formato h:mm, por exemplo 19:30 para dezenove horas e meia. Mistura no formato dia/mês hora:minuto.
A9: PARÂMETROS · o que você edita
A10: Parâmetro | B10: B · Morbida 55% | C10: C · Umida 65% | D10: Observação
A11: Mistura da biga | B11: 46239.604 | C11: 46239.927 | D11: editável, dispara todo o resto
A12: Arranque a 20 °C | B12: 0.041666667 | C12: 0.03125 | D12: antes de ir para o frio
A13: Câmara a 4 °C | B13: 0.8125 | C13: 0.625 | D13: encurtada na revisão 2 para caber no horário
A14: Risveglio a 21 °C | B14: 0.125 | C14: 0.083333333 | D14: compensa a câmara mais curta
A15: Mistura do rinfresco | B15: 0.013888889 | C15: 0.013888889 | D15: água a fio, sal na última adição
A16: Puntata a 22 a 24 °C | B16: 0.12152778 | C16: 0.038194444 | D16: absorve a diferença entre os dois braços
A17: Appretto a 18 °C | B17: 0.19791667 | C17: 0.19791667 | D17: igual nos dois braços, de propósito
A18: Checagem 1, horas de câmara | B18: 0.3125 | C18: 0.33333333 | D18: leitura no testemunho de 200 g
A19: Checagem 2, horas de câmara | B19: 0.6875 | C19: 0.54166667 | D19: leitura no testemunho de 200 g
A20: Total, da mistura ao forno | B20: =SUM(B12:B17) -> 1.3125 | C20: =SUM(C12:C17) -> 0.98958333 | D20: soma das durações, sem contar as checagens
A22: CRONOGRAMA · BRAÇO B · BIGA A 55% · FERMENTO 0,9%
A23: Etapa | B23: Previsto | C23: Hora real | D23: pH observado
A24: Mistura da biga | B24: =IF($B$11="","",$B$11) -> 46239.604
A25: Entra na câmara a 4 °C | B25: =IF($B24="","",$B24+$B$12) -> 46239.646
A26: Checagem 1 | B26: =IF($B25="","",$B25+$B$18) -> 46239.958
A27: Checagem 2 | B27: =IF($B25="","",$B25+$B$19) -> 46240.333
A28: Sai da câmara | B28: =IF($B25="","",$B25+$B$13) -> 46240.458
A29: Rinfresco, início | B29: =IF($B28="","",$B28+$B$14) -> 46240.583
A30: Rinfresco, fim da mistura | B30: =IF($B29="","",$B29+$B$15) -> 46240.597
A31: Staglio, 6 × 290 g | B31: =IF($B30="","",$B30+$B$16) -> 46240.719
A32: Forno | B32: =IF($B31="","",$B31+$B$17) -> 46240.917
A34: CRONOGRAMA · BRAÇO C · BIGA A 65% · FERMENTO 0,55%
A35: Etapa | B35: Previsto | C35: Hora real | D35: pH observado
A36: Mistura da biga | B36: =IF($C$11="","",$C$11) -> 46239.927
A37: Entra na câmara a 4 °C | B37: =IF($B36="","",$B36+$C$12) -> 46239.958
A38: Checagem 1 | B38: =IF($B37="","",$B37+$C$18) -> 46240.292
A39: Checagem 2 | B39: =IF($B37="","",$B37+$C$19) -> 46240.5
A40: Sai da câmara | B40: =IF($B37="","",$B37+$C$13) -> 46240.583
A41: Rinfresco, início | B41: =IF($B40="","",$B40+$C$14) -> 46240.667
A42: Rinfresco, fim da mistura | B42: =IF($B41="","",$B41+$C$15) -> 46240.681
A43: Staglio, 6 × 290 g | B43: =IF($B42="","",$B42+$C$16) -> 46240.719
A44: Forno | B44: =IF($B43="","",$B43+$C$17) -> 46240.917
...

Sheet De trás para frente
A1: A QUE HORA BATER CADA BIGA
A2: Você informa a hora do forno e a planilha devolve os horários. Usa as mesmas durações da aba Cronograma.
A4: Forno desejado | B4: 46240.917 | C4: editável
A6: HORÁRIOS CALCULADOS DE TRÁS PARA FRENTE
A7: Etapa | B7: B · Morbida 55% | C7: C · Umida 65%
A8: Mistura da biga | B8: =IF($B$4="","",$B$4-Cronograma!$B$20) -> 46239.604 | C8: =IF($B$4="","",$B$4-Cronograma!$C$20) -> 46239.927
A9: Entra na câmara a 4 °C | B9: =IF(B8="","",B8+Cronograma!$B$12) -> 46239.646 | C9: =IF(C8="","",C8+Cronograma!$C$12) -> 46239.958
A10: Checagem 1 | B10: =IF(B$9="","",B$9+Cronograma!$B$18) -> 46239.958 | C10: =IF(C$9="","",C$9+Cronograma!$C$18) -> 46240.292
A11: Checagem 2 | B11: =IF(B$9="","",B$9+Cronograma!$B$19) -> 46240.333 | C11: =IF(C$9="","",C$9+Cronograma!$C$19) -> 46240.5
A12: Sai da câmara | B12: =IF(B$9="","",B$9+Cronograma!$B$13) -> 46240.458 | C12: =IF(C$9="","",C$9+Cronograma!$C$13) -> 46240.583
A13: Rinfresco, início | B13: =IF(B$12="","",B$12+Cronograma!$B$14) -> 46240.583 | C13: =IF(C$12="","",C$12+Cronograma!$C$14) -> 46240.667
A14: Rinfresco, fim da mistura | B14: =IF(B$13="","",B$13+Cronograma!$B$15) -> 46240.597 | C14: =IF(C$13="","",C$13+Cronograma!$C$15) -> 46240.681
A15: Staglio, 6 × 290 g | B15: =IF(B$14="","",B$14+Cronograma!$B$16) -> 46240.719 | C15: =IF(C$14="","",C$14+Cronograma!$C$16) -> 46240.719
A16: Forno | B16: =IF(B$15="","",B$15+Cronograma!$B$17) -> 46240.917 | C16: =IF(C$15="","",C$15+Cronograma!$C$17) -> 46240.917
A18: A última linha tem que bater exatamente com o forno desejado. Se não bater, alguma duração da aba Cronograma foi editada no meio do caminho.
A19: Verde indica valor que vem da aba Cronograma. Azul é o que você digita.
