Workbook

Sheet Massa
A1: QT PIZZA BAR · MASSA COM BIGA
A2: Blend de três farinhas · biga a 37% da farinha · 75% de hidratação final
A4: COMO USAR
A5: Edite só as células amarelas. Todo o resto é fórmula e se recalcula sozinho.
A6: A hidratação da biga é a variável do ensaio. Mudando ela, a água se desloca da biga para o rinfresco e vice-versa: a soma continua 75%.
A7: As porcentagens de farinha são sempre sobre a farinha total, do jeito que você já conta a receita.
A9: RENDIMENTO · quanto você quer produzir
A10: Número de bolas | B10: 20
A11: Peso da bola | B11: 250
A12: Perda de processo | B12: 0.02 | C12: resto de masseira, bancada, sobra de staglio
A13: Massa total a produzir | B13: =B10*B11*(1+B12) -> 5100
A15: FÓRMULA · percentuais do padeiro, sobre a farinha total
A16: Hidratação final | B16: 0.75 | C16: alvo da QT e dos braços do ensaio
A17: Sal | B17: 0.027 | C17: entra todo no rinfresco
A18: Fermento fresco, sobre a farinha DA BIGA | B18: 0.009 | C18: atenção: base é a farinha da biga, não a total
A19: Biga, fração da farinha total | B19: 0.37 | C19: sua receita: 10% Marrone + 27% Viola
A20: Hidratação da biga | B20: 0.55 | C20: a variável do ensaio
A21: Farinha total | B21: =B13/(1+B16+B17+B19*B18) -> 2864.6375 | C21: derivada do rendimento e dos percentuais
A22: Água total | B22: =B21*B16 -> 2148.4781
A23: Sal total | B23: =B21*B17 -> 77.345211
A25: BLEND · percentuais sobre a farinha total
A26: Farinha | B26: Na biga | C26: No rinfresco | D26: Total
A27: Marrone | B27: 0.1 | C27: 0 | D27: =B27+C27 -> 0.1
A28: Viola | B28: 0.27 | C28: 0.28 | D28: =B28+C28 -> 0.55
A29: Verde | B29: 0 | C29: 0.35 | D29: =B29+C29 -> 0.35
A30: Total | B30: =SUM(B27:B29) -> 0.37 | C30: =SUM(C27:C29) -> 0.63 | D30: =SUM(D27:D29) -> 1
A31: =IF(AND(ABS($B$30-$B$19)<0.0001,ABS($D$30-1)<0.0001),"Blend fecha: a coluna da biga bate com a fração da biga e o total dá 100%.","ATENÇÃO: o blend não fecha. A coluna Na biga tem que somar a fração da biga, e o Total tem que dar 100%.") -> Blend fecha: a coluna da biga bate com a fração da biga e o total dá 100%.
A33: PESAGEM DA BIGA
A34: Ingrediente | B34: Peso | C34: % s/ farinha total
A35: Marrone | B35: =$B$21*$B$27 -> 286.46375 | C35: =$B$27 -> 0.1
A36: Viola | B36: =$B$21*$B$28 -> 773.45211 | C36: =$B$28 -> 0.27
A37: Verde | B37: =$B$21*$B$29 -> 0 | C37: =$B$29 -> 0
A38: Água gelada | B38: =$B$21*$B$19*$B$20 -> 582.95372 | C38: =$B$19*$B$20 -> 0.2035
A39: Fermento fresco | B39: =$B$21*$B$19*$B$18 -> 9.5392427 | C39: =$B$19*$B$18 -> 0.00333
A40: Total da biga | B40: =SUM(B35:B39) -> 1652.4088
A41: Mistura curta, 4 a 5 min em v1. A biga não precisa ficar lisa.
A43: PESAGEM DO RINFRESCO
A44: Ingrediente | B44: Peso | C44: % s/ farinha total
A45: Biga inteira | B45: =$B$40 -> 1652.4088
A46: Marrone | B46: =$B$21*$C$27 -> 0 | C46: =$C$27 -> 0
...

Sheet Três braços
A1: OS TRÊS BRAÇOS NA MASSA DA QT
A2: Mesma estrutura de receita, mesma hidratação final, mesmo blend. Só muda a hidratação da biga e a dose de fermento.
A3: Rendimento, blend, sal e hidratação final vêm da aba Massa. Edite lá e os três braços acompanham.
A5: VARIÁVEIS DE CADA BRAÇO
B6: A · Fredda | C6: B · Morbida | D6: C · Umida
A7: Hidratação da biga | B7: 0.45 | C7: 0.55 | D7: 0.65
A8: Fermento s/ farinha da biga | B8: 0.01 | C8: 0.009 | D8: 0.0055
A10: PESAGEM · gramas por braço
A11: Ingrediente | B11: A · 45% | C11: B · 55% | D11: C · 65%
A12: Marrone | B12: =(Massa!$B$13/(1+Massa!$B$16+Massa!$B$17+Massa!$B$19*B$8))*Massa!$B$27 -> 286.40422 | C12: =(Massa!$B$13/(1+Massa!$B$16+Massa!$B$17+Massa!$B$19*C$8))*Massa!$B$27 -> 286.46375 | D12: =(Massa!$B$13/(1+Massa!$B$16+Massa!$B$17+Massa!$B$19*D$8))*Massa!$B$27 -> 286.67227
A13: Viola | B13: =(Massa!$B$13/(1+Massa!$B$16+Massa!$B$17+Massa!$B$19*B$8))*Massa!$B$28 -> 773.2914 | C13: =(Massa!$B$13/(1+Massa!$B$16+Massa!$B$17+Massa!$B$19*C$8))*Massa!$B$28 -> 773.45211 | D13: =(Massa!$B$13/(1+Massa!$B$16+Massa!$B$17+Massa!$B$19*D$8))*Massa!$B$28 -> 774.01513
A14: Verde | B14: =(Massa!$B$13/(1+Massa!$B$16+Massa!$B$17+Massa!$B$19*B$8))*Massa!$B$29 -> 0 | C14: =(Massa!$B$13/(1+Massa!$B$16+Massa!$B$17+Massa!$B$19*C$8))*Massa!$B$29 -> 0 | D14: =(Massa!$B$13/(1+Massa!$B$16+Massa!$B$17+Massa!$B$19*D$8))*Massa!$B$29 -> 0
A15: Água gelada | B15: =(Massa!$B$13/(1+Massa!$B$16+Massa!$B$17+Massa!$B$19*B$8))*Massa!$B$19*B$7 -> 476.86303 | C15: =(Massa!$B$13/(1+Massa!$B$16+Massa!$B$17+Massa!$B$19*C$8))*Massa!$B$19*C$7 -> 582.95372 | D15: =(Massa!$B$13/(1+Massa!$B$16+Massa!$B$17+Massa!$B$19*D$8))*Massa!$B$19*D$7 -> 689.44681
A16: Fermento fresco | B16: =(Massa!$B$13/(1+Massa!$B$16+Massa!$B$17+Massa!$B$19*B$8))*Massa!$B$19*B$8 -> 10.596956 | C16: =(Massa!$B$13/(1+Massa!$B$16+Massa!$B$17+Massa!$B$19*C$8))*Massa!$B$19*C$8 -> 9.5392427 | D16: =(Massa!$B$13/(1+Massa!$B$16+Massa!$B$17+Massa!$B$19*D$8))*Massa!$B$19*D$8 -> 5.8337807
A17: Total da biga | B17: =SUM(B12:B16) -> 1547.1556 | C17: =SUM(C12:C16) -> 1652.4088 | D17: =SUM(D12:D16) -> 1755.968
A18: Marrone | B18: =(Massa!$B$13/(1+Massa!$B$16+Massa!$B$17+Massa!$B$19*B$8))*Massa!$C$27 -> 0 | C18: =(Massa!$B$13/(1+Massa!$B$16+Massa!$B$17+Massa!$B$19*C$8))*Massa!$C$27 -> 0 | D18: =(Massa!$B$13/(1+Massa!$B$16+Massa!$B$17+Massa!$B$19*D$8))*Massa!$C$27 -> 0
A19: Viola | B19: =(Massa!$B$13/(1+Massa!$B$16+Massa!$B$17+Massa!$B$19*B$8))*Massa!$C$28 -> 801.93182 | C19: =(Massa!$B$13/(1+Massa!$B$16+Massa!$B$17+Massa!$B$19*C$8))*Massa!$C$28 -> 802.09849 | D19: =(Massa!$B$13/(1+Massa!$B$16+Massa!$B$17+Massa!$B$19*D$8))*Massa!$C$28 -> 802.68235
A20: Verde | B20: =(Massa!$B$13/(1+Massa!$B$16+Massa!$B$17+Massa!$B$19*B$8))*Massa!$C$29 -> 1002.4148 | C20: =(Massa!$B$13/(1+Massa!$B$16+Massa!$B$17+Massa!$B$19*C$8))*Massa!$C$29 -> 1002.6231 | D20: =(Massa!$B$13/(1+Massa!$B$16+Massa!$B$17+Massa!$B$19*D$8))*Massa!$C$29 -> 1003.3529
A21: Água | B21: =(Massa!$B$13/(1+Massa!$B$16+Massa!$B$17+Massa!$B$19*B$8))*(Massa!$B$16-Massa!$B$19*B$7) -> 1671.1686 | C21: =(Massa!$B$13/(1+Massa!$B$16+Massa!$B$17+Massa!$B$19*C$8))*(Massa!$B$16-Massa!$B$19*C$7) -> 1565.5244 | D21: =(Massa!$B$13/(1+Massa!$B$16+Massa!$B$17+Massa!$B$19*D$8))*(Massa!$B$16-Massa!$B$19*D$7) -> 1460.5952
A22: Sal | B22: =(Massa!$B$13/(1+Massa!$B$16+Massa!$B$17+Massa!$B$19*B$8))*Massa!$B$17 -> 77.32914 | C22: =(Massa!$B$13/(1+Massa!$B$16+Massa!$B$17+Massa!$B$19*C$8))*Massa!$B$17 -> 77.345211 | D22: =(Massa!$B$13/(1+Massa!$B$16+Massa!$B$17+Massa!$B$19*D$8))*Massa!$B$17 -> 77.401513
A23: Total da massa | B23: =B17+SUM(B18:B22) -> 5100 | C23: =C17+SUM(C18:C22) -> 5100 | D23: =D17+SUM(D18:D22) -> 5100
A25: O QUE MUDA ENTRE OS BRAÇOS
B26: A · 45% | C26: B · 55% | D26: C · 65%
A27: Hidratação sobre a farinha do rinfresco | B27: =(Massa!$B$16-Massa!$B$19*B$7)/(1-Massa!$B$19) -> 0.92619048 | C27: =(Massa!$B$16-Massa!$B$19*C$7)/(1-Massa!$B$19) -> 0.86746032 | D27: =(Massa!$B$16-Massa!$B$19*D$7)/(1-Massa!$B$19) -> 0.80873016
A28: Água na biga | B28: =(Massa!$B$13/(1+Massa!$B$16+Massa!$B$17+Massa!$B$19*B$8))*Massa!$B$19*B$7 -> 476.86303 | C28: =(Massa!$B$13/(1+Massa!$B$16+Massa!$B$17+Massa!$B$19*C$8))*Massa!$B$19*C$7 -> 582.95372 | D28: =(Massa!$B$13/(1+Massa!$B$16+Massa!$B$17+Massa!$B$19*D$8))*Massa!$B$19*D$7 -> 689.44681
A29: Água no rinfresco | B29: =(Massa!$B$13/(1+Massa!$B$16+Massa!$B$17+Massa!$B$19*B$8))*(Massa!$B$16-Massa!$B$19*B$7) -> 1671.1686 | C29: =(Massa!$B$13/(1+Massa!$B$16+Massa!$B$17+Massa!$B$19*C$8))*(Massa!$B$16-Massa!$B$19*C$7) -> 1565.5244 | D29: =(Massa!$B$13/(1+Massa!$B$16+Massa!$B$17+Massa!$B$19*D$8))*(Massa!$B$16-Massa!$B$19*D$7) -> 1460.5952
A30: Fermento em % da farinha total | B30: =Massa!$B$19*B$8 -> 0.0037 | C30: =Massa!$B$19*C$8 -> 0.00333 | D30: =Massa!$B$19*D$8 -> 0.002035
A32: A linha 27 é a leitura mais importante desta aba. A hidratação final é 75% nos três, mas a farinha que entra seca no rinfresco recebe quase 93% no braço A e 81% no braço C. São massas bem diferentes de fechar, e boa parte do que você vai sentir vem daí, não da biga em si.
A34: Verde indica valor calculado a partir da aba Massa. Azul é o que você digita.
